[32m2025-10-21 10:58:15 +0200[0m - dagster - [34mDEBUG[0m - __ASSET_JOB - 7b3b4503-9f57-4a82-aba7-92477eeef83a - 81742 - LOGS_CAPTURED - Started capturing logs in process (pid: 81742).
[32m2025-10-21 10:58:15 +0200[0m - dagster - [34mDEBUG[0m - __ASSET_JOB - 7b3b4503-9f57-4a82-aba7-92477eeef83a - 81742 - dbt_models - STEP_START - Started execution of step "dbt_models".
[32m2025-10-21 10:58:15 +0200[0m - dagster - [34mINFO[0m - __ASSET_JOB - 7b3b4503-9f57-4a82-aba7-92477eeef83a - dbt_models - A dbt subsetted execution is not being performed. Using the default dbt selection arguments `['--select', 'fqn:*']`.
[32m2025-10-21 10:58:17 +0200[0m - dagster - [34mINFO[0m - __ASSET_JOB - 7b3b4503-9f57-4a82-aba7-92477eeef83a - dbt_models - Copying `/Users/kidquatro/Documents/STI-DE24/Big Data Cloud/Big-Data-and-Cloud-Group-8/data_transformation/target/partial_parse.msgpack` to `/Users/kidquatro/Documents/STI-DE24/Big Data Cloud/Big-Data-and-Cloud-Group-8/data_transformation/target/dbt_models-7b3b450-0411048/partial_parse.msgpack` to take advantage of partial parsing.
[32m2025-10-21 10:58:17 +0200[0m - dagster - [34mINFO[0m - __ASSET_JOB - 7b3b4503-9f57-4a82-aba7-92477eeef83a - dbt_models - Running dbt command: `dbt build --select fqn:*`.
[32m2025-10-21 10:58:19 +0200[0m - dagster - [34mINFO[0m - __ASSET_JOB - 7b3b4503-9f57-4a82-aba7-92477eeef83a - dbt_models - Finished dbt command: `dbt build --select fqn:*`.
[32m2025-10-21 10:58:19 +0200[0m - dagster - [34mERROR[0m - [31m__ASSET_JOB - 7b3b4503-9f57-4a82-aba7-92477eeef83a - 81742 - dbt_models - STEP_FAILURE - Execution of step "dbt_models" failed.

dagster_dbt.errors.DagsterDbtCliRuntimeError: The dbt CLI process with command

`dbt build --select fqn:*`

failed with exit code `1`. Check the stdout in the Dagster compute logs for the full information about the error, or view the dbt debug log: /Users/kidquatro/Documents/STI-DE24/Big Data Cloud/Big-Data-and-Cloud-Group-8/data_transformation/target/dbt_models-7b3b450-0411048/dbt.log.

Errors parsed from dbt logs:

1 of 17 ERROR creating sql table model marts.marts_bygg ........................ [[31mERROR[0m in 0.04s]

2 of 17 ERROR creating sql table model marts.marts_kultur ...................... [[31mERROR[0m in 0.01s]

3 of 17 ERROR creating sql table model marts.marts_pedagogik ................... [[31mERROR[0m in 0.01s]

4 of 17 ERROR creating sql table model warehouse.dim_auxilliary_attributes ..... [[31mERROR[0m in 0.02s]

5 of 17 ERROR creating sql table model warehouse.dim_employer .................. [[31mERROR[0m in 0.02s]

6 of 17 ERROR creating sql table model warehouse.fct_job_ads ................... [[31mERROR[0m in 0.02s]

7 of 17 ERROR creating sql table model warehouse.dim_job_details ............... [[31mERROR[0m in 0.01s]

8 of 17 ERROR creating sql table model warehouse.dim_occupation ................ [[31mERROR[0m in 0.01s]

[31mFailure in model marts_bygg (models/mart/marts_bygg.sql)[0m

  Runtime Error in model marts_bygg (models/mart/marts_bygg.sql)
  Catalog Error: Table with name fct_job_ads does not exist!
  Did you mean "duckdb_tables"?
  
  LINE 38: FROM fct_job_ads f
                ^

[31mFailure in model marts_kultur (models/mart/marts_kultur.sql)[0m

  Runtime Error in model marts_kultur (models/mart/marts_kultur.sql)
  Catalog Error: Table with name fct_job_ads does not exist!
  Did you mean "duckdb_tables"?
  
  LINE 38: FROM fct_job_ads f
                ^

[31mFailure in model marts_pedagogik (models/mart/marts_pedagogik.sql)[0m

  Runtime Error in model marts_pedagogik (models/mart/marts_pedagogik.sql)
  Catalog Error: Table with name fct_job_ads does not exist!
  Did you mean "duckdb_tables"?
  
  LINE 38: FROM fct_job_ads f
                ^

[31mFailure in model dim_auxilliary_attributes (models/dim/dim_auxilliary_attributes.sql)[0m

  Runtime Error in model dim_auxilliary_attributes (models/dim/dim_auxilliary_attributes.sql)
  Catalog Error: Table with name project_job_ads does not exist!
  Did you mean "pg_catalog.pg_tables"?
  
  LINE 12: with stg_job_ads as (select * from "job_ads"."staging"."project_job_ads")
                                              ^

[31mFailure in model dim_employer (models/dim/dim_employer.sql)[0m

  Runtime Error in model dim_employer (models/dim/dim_employer.sql)
  Catalog Error: Table with name project_job_ads does not exist!
  Did you mean "pg_catalog.pg_tables"?
  
  LINE 12: with stg_job_ads as (select * from "job_ads"."staging"."project_job_ads")
                                              ^

[31mFailure in model fct_job_ads (models/fct/fct_job_ads.sql)[0m

  Runtime Error in model fct_job_ads (models/fct/fct_job_ads.sql)
  Catalog Error: Table with name project_job_ads does not exist!
  Did you mean "pg_catalog.pg_tables"?
  
  LINE 12: with stg_job_ads as (select * from "job_ads"."staging"."project_job_ads")
                                              ^

[31mFailure in model dim_job_details (models/dim/dim_job_details.sql)[0m

  Runtime Error in model dim_job_details (models/dim/dim_job_details.sql)
  Catalog Error: Table with name project_job_ads does not exist!
  Did you mean "pg_catalog.pg_tables"?
  
  LINE 12: with stg_job_ads as (select * from "job_ads"."staging"."project_job_ads")
                                              ^

[31mFailure in model dim_occupation (models/dim/dim_occupation.sql)[0m

  Runtime Error in model dim_occupation (models/dim/dim_occupation.sql)
  Catalog Error: Table with name project_job_ads does not exist!
  Did you mean "pg_catalog.pg_tables"?
  
  LINE 12: with stg_job_ads as (select * from "job_ads"."staging"."project_job_ads")
                                              ^

Stack Trace:
  File "/Users/kidquatro/Documents/STI-DE24/Big Data Cloud/Big-Data-and-Cloud-Group-8/.venv/lib/python3.13/site-packages/dagster/_core/execution/plan/execute_plan.py", line 247, in dagster_event_sequence_for_step
    yield from check.generator(step_events)
  File "/Users/kidquatro/Documents/STI-DE24/Big Data Cloud/Big-Data-and-Cloud-Group-8/.venv/lib/python3.13/site-packages/dagster/_core/execution/plan/execute_step.py", line 504, in core_dagster_event_sequence_for_step
    for user_event in _step_output_error_checked_user_event_sequence(
                      ~~~~~~~~~~~~~~~~~~~~~~~~~~~~~~~~~~~~~~~~~~~~~~^
        step_context,
        ^^^^^^^^^^^^^
        _process_asset_results_to_events(step_context, user_event_sequence),
        ^^^^^^^^^^^^^^^^^^^^^^^^^^^^^^^^^^^^^^^^^^^^^^^^^^^^^^^^^^^^^^^^^^^^
    ):
    ^
  File "/Users/kidquatro/Documents/STI-DE24/Big Data Cloud/Big-Data-and-Cloud-Group-8/.venv/lib/python3.13/site-packages/dagster/_core/execution/plan/execute_step.py", line 183, in _step_output_error_checked_user_event_sequence
    for user_event in user_event_sequence:
                      ^^^^^^^^^^^^^^^^^^^
  File "/Users/kidquatro/Documents/STI-DE24/Big Data Cloud/Big-Data-and-Cloud-Group-8/.venv/lib/python3.13/site-packages/dagster/_core/execution/plan/execute_step.py", line 88, in _process_asset_results_to_events
    for user_event in user_event_sequence:
                      ^^^^^^^^^^^^^^^^^^^
  File "/Users/kidquatro/Documents/STI-DE24/Big Data Cloud/Big-Data-and-Cloud-Group-8/.venv/lib/python3.13/site-packages/dagster/_core/execution/plan/compute.py", line 190, in execute_core_compute
    for step_output in _yield_compute_results(step_context, inputs, compute_fn, compute_context):
                       ~~~~~~~~~~~~~~~~~~~~~~^^^^^^^^^^^^^^^^^^^^^^^^^^^^^^^^^^^^^^^^^^^^^^^^^^^
  File "/Users/kidquatro/Documents/STI-DE24/Big Data Cloud/Big-Data-and-Cloud-Group-8/.venv/lib/python3.13/site-packages/dagster/_core/execution/plan/compute.py", line 159, in _yield_compute_results
    for event in iterate_with_context(
                 ~~~~~~~~~~~~~~~~~~~~^
        lambda: op_execution_error_boundary(
        ^^^^^^^^^^^^^^^^^^^^^^^^^^^^^^^^^^^^
    ...<7 lines>...
        user_event_generator,
        ^^^^^^^^^^^^^^^^^^^^^
    ):
    ^
  File "/Users/kidquatro/Documents/STI-DE24/Big Data Cloud/Big-Data-and-Cloud-Group-8/.venv/lib/python3.13/site-packages/dagster/_utils/__init__.py", line 392, in iterate_with_context
    next_output = next(iterator)
  File "/Users/kidquatro/Documents/STI-DE24/Big Data Cloud/Big-Data-and-Cloud-Group-8/orchestration/definitions.py", line 65, in dbt_models
    yield from dbt.cli(["build"], context=context).stream()
  File "/Users/kidquatro/Documents/STI-DE24/Big Data Cloud/Big-Data-and-Cloud-Group-8/.venv/lib/python3.13/site-packages/dagster_dbt/core/dbt_event_iterator.py", line 215, in __next__
    return next(self._inner_iterator)
  File "/Users/kidquatro/Documents/STI-DE24/Big Data Cloud/Big-Data-and-Cloud-Group-8/.venv/lib/python3.13/site-packages/dagster_dbt/core/dbt_cli_invocation.py", line 289, in _stream_asset_events
    for event in self.stream_raw_events():
                 ~~~~~~~~~~~~~~~~~~~~~~^^
  File "/Users/kidquatro/Documents/STI-DE24/Big Data Cloud/Big-Data-and-Cloud-Group-8/.venv/lib/python3.13/site-packages/dagster_dbt/core/dbt_cli_invocation.py", line 382, in stream_raw_events
    self._raise_on_error()
    ~~~~~~~~~~~~~~~~~~~~^^
  File "/Users/kidquatro/Documents/STI-DE24/Big Data Cloud/Big-Data-and-Cloud-Group-8/.venv/lib/python3.13/site-packages/dagster_dbt/core/dbt_cli_invocation.py", line 475, in _raise_on_error
    raise error
[0m
